Workbook

Sheet Start here
A2: Mileage & Expense Log 2026
A3: How to use this workbook · Powered by BlueLine Advisors
A5: Start on the Log sheet
A6: Pick the tax year and your line of work. The sheet then lists what people in your work usually forget to log, and what they tend to claim that is not deductible.
A7: Travel — one row per trip: date, client, where and why, miles, purpose. The IRS rate for that date and the total fill in by themselves.
A8: Expenses — one row per cost: date, client or vendor, what and why, amount, category. The sheet shows how the category is usually treated, whether it is typical for your work, and any watch-out for your line of work.
A9: Summary — the year-end report: estimated deductions, miles by purpose, expenses by treatment, and the notes for your line of work.
A11: How expenses are counted
A12: Deductible — counted in full. Partly deductible — counted at the allowed share (business meals at 50%). For your CPA — recorded and totaled separately, not counted, because the answer depends on facts the log cannot see (business-use %, cost per item, exclusive use). Not deductible — recorded so your CPA sees it, counted at zero.
A14: Rules of thumb
A15: Keep the log as you go. A reconstructed log is the first thing an auditor challenges.
A16: Commuting from home to your regular workplace is not deductible, whatever you carry or discuss on the way.
... A30: The Client Decision Support Toolkit and its templates are built and maintained for Grott Luker & Co. by BlueLine Advisors, LLC, an SEC-registered investment adviser in Exeter, NH (registration does not imply any particular level of skill). Using this workbook does not create an advisory relationship with BlueLine.

Sheet Log
F2: Log
F3: Tax year and your line of work · Powered by BlueLine Advisors
A5: Tax year
A6: Tax year | B6: 2026
A7: IRS standard rates apply automatically by each trip's date. Verify against irs.gov every January.
A8: Your line of work
A9: What kind of work is this log for? | B9: Other / general business
A10: Picking your line of work changes the two lists below and marks your usual categories on the Expenses sheet. The rules are general; your CPA decides.
A12: Rates in use | F12: dollars per mile
A13: FROM | C13: BUSINESS | D13: CHARITY | E13: MEDICAL
A14: =Guide!A83 | C14: =Guide!B83 | D14: =Guide!C83 | E14: =Guide!D83
A15: =Guide!A84 | C15: =Guide!B84 | D15: =Guide!C84 | E15: =Guide!D84
A16: =Guide!A85 | C16: =Guide!B85 | D16: =Guide!C85 | E16: =Guide!D85
A17: =Guide!A86 | C17: =Guide!B86 | D17: =Guide!C86 | E17: =Guide!D86
A19: Usually not deductible | F19: for your line of work
A20: =T(INDEX(Guide!$E$39:$R$41,1,Guide!$B$6)) | B20: =T(INDEX(Guide!$E$44:$R$46,1,Guide!$B$6))
A21: =T(INDEX(Guide!$E$39:$R$41,2,Guide!$B$6)) | B21: =T(INDEX(Guide!$E$44:$R$46,2,Guide!$B$6))
A22: =T(INDEX(Guide!$E$39:$R$41,3,Guide!$B$6)) | B22: =T(INDEX(Guide!$E$44:$R$46,3,Guide!$B$6))
A24: Pay extra attention to these | F24: people in your work tend to forget to log them
A25: ITEM | B25: CATEGORY | C25: TREATMENT
A26: =T(INDEX(Guide!$E$11:$R$22,1,Guide!$B$6)) | B26: =T(INDEX(Guide!$E$25:$R$36,1,Guide!$B$6)) | C26: =IF(B26="","",INDEX(Guide!$B$51:$B$78,MATCH(B26,Guide!$A$51:$A$78,0)))
A27: =T(INDEX(Guide!$E$11:$R$22,2,Guide!$B$6)) | B27: =T(INDEX(Guide!$E$25:$R$36,2,Guide!$B$6)) | C27: =IF(B27="","",INDEX(Guide!$B$51:$B$78,MATCH(B27,Guide!$A$51:$A$78,0)))
A28: =T(INDEX(Guide!$E$11:$R$22,3,Guide!$B$6)) | B28: =T(INDEX(Guide!$E$25:$R$36,3,Guide!$B$6)) | C28: =IF(B28="","",INDEX(Guide!$B$51:$B$78,MATCH(B28,Guide!$A$51:$A$78,0)))
A29: =T(INDEX(Guide!$E$11:$R$22,4,Guide!$B$6)) | B29: =T(INDEX(Guide!$E$25:$R$36,4,Guide!$B$6)) | C29: =IF(B29="","",INDEX(Guide!$B$51:$B$78,MATCH(B29,Guide!$A$51:$A$78,0)))
A30: =T(INDEX(Guide!$E$11:$R$22,5,Guide!$B$6)) | B30: =T(INDEX(Guide!$E$25:$R$36,5,Guide!$B$6)) | C30: =IF(B30="","",INDEX(Guide!$B$51:$B$78,MATCH(B30,Guide!$A$51:$A$78,0)))
A31: =T(INDEX(Guide!$E$11:$R$22,6,Guide!$B$6)) | B31: =T(INDEX(Guide!$E$25:$R$36,6,Guide!$B$6)) | C31: =IF(B31="","",INDEX(Guide!$B$51:$B$78,MATCH(B31,Guide!$A$51:$A$78,0)))
A32: =T(INDEX(Guide!$E$11:$R$22,7,Guide!$B$6)) | B32: =T(INDEX(Guide!$E$25:$R$36,7,Guide!$B$6)) | C32: =IF(B32="","",INDEX(Guide!$B$51:$B$78,MATCH(B32,Guide!$A$51:$A$78,0)))
A33: =T(INDEX(Guide!$E$11:$R$22,8,Guide!$B$6)) | B33: =T(INDEX(Guide!$E$25:$R$36,8,Guide!$B$6)) | C33: =IF(B33="","",INDEX(Guide!$B$51:$B$78,MATCH(B33,Guide!$A$51:$A$78,0)))
A34: =T(INDEX(Guide!$E$11:$R$22,9,Guide!$B$6)) | B34: =T(INDEX(Guide!$E$25:$R$36,9,Guide!$B$6)) | C34: =IF(B34="","",INDEX(Guide!$B$51:$B$78,MATCH(B34,Guide!$A$51:$A$78,0)))
A35: =T(INDEX(Guide!$E$11:$R$22,10,Guide!$B$6)) | B35: =T(INDEX(Guide!$E$25:$R$36,10,Guide!$B$6)) | C35: =IF(B35="","",INDEX(Guide!$B$51:$B$78,MATCH(B35,Guide!$A$51:$A$78,0)))
A36: =T(INDEX(Guide!$E$11:$R$22,11,Guide!$B$6)) | B36: =T(INDEX(Guide!$E$25:$R$36,11,Guide!$B$6)) | C36: =IF(B36="","",INDEX(Guide!$B$51:$B$78,MATCH(B36,Guide!$A$51:$A$78,0)))
A37: =T(INDEX(Guide!$E$11:$R$22,12,Guide!$B$6)) | B37: =T(INDEX(Guide!$E$25:$R$36,12,Guide!$B$6)) | C37: =IF(B37="","",INDEX(Guide!$B$51:$B$78,MATCH(B37,Guide!$A$51:$A$78,0)))
A39: Prepared for planning with Grott Luker & Co. This workbook organizes your records; it does not determine what is deductible. Entries are your own; review with your Grott Luker CPA before anything is used in a return or a decision.

Sheet Travel
G2: Travel
G3: ="Tax year "&Log!$B$6&" · Powered by BlueLine Advisors" · Powered by BlueLine Advisors
A5: Trips | G5: the rate and total fill in from the date and purpose
A6: DATE | B6: CLIENT | C6: DESCRIPTION & DESTINATION | D6: MILES | E6: PURPOSE ▾ | F6: RATE | G6: TOTAL
F7: =IF(OR(A7="",E7=""),"",INDEX(Guide!$B$83:$D$86,MATCH(A7,Guide!$A$83:$A$86,1),MATCH(E7,Guide!$B$82:$D$82,0))) | G7: =IF(F7="","",D7*F7)
F8: =IF(OR(A8="",E8=""),"",INDEX(Guide!$B$83:$D$86,MATCH(A8,Guide!$A$83:$A$86,1),MATCH(E8,Guide!$B$82:$D$82,0))) | G8: =IF(F8="","",D8*F8)
F9: =IF(OR(A9="",E9=""),"",INDEX(Guide!$B$83:$D$86,MATCH(A9,Guide!$A$83:$A$86,1),MATCH(E9,Guide!$B$82:$D$82,0))) | G9: =IF(F9="","",D9*F9)
F10: =IF(OR(A10="",E10=""),"",INDEX(Guide!$B$83:$D$86,MATCH(A10,Guide!$A$83:$A$86,1),MATCH(E10,Guide!$B$82:$D$82,0))) | G10: =IF(F10="","",D10*F10)
F11: =IF(OR(A11="",E11=""),"",INDEX(Guide!$B$83:$D$86,MATCH(A11,Guide!$A$83:$A$86,1),MATCH(E11,Guide!$B$82:$D$82,0))) | G11: =IF(F11="","",D11*F11)
F12: =IF(OR(A12="",E12=""),"",INDEX(Guide!$B$83:$D$86,MATCH(A12,Guide!$A$83:$A$86,1),MATCH(E12,Guide!$B$82:$D$82,0))) | G12: =IF(F12="","",D12*F12)
F13: =IF(OR(A13="",E13=""),"",INDEX(Guide!$B$83:$D$86,MATCH(A13,Guide!$A$83:$A$86,1),MATCH(E13,Guide!$B$82:$D$82,0))) | G13: =IF(F13="","",D13*F13)
F14: =IF(OR(A14="",E14=""),"",INDEX(Guide!$B$83:$D$86,MATCH(A14,Guide!$A$83:$A$86,1),MATCH(E14,Guide!$B$82:$D$82,0))) | G14: =IF(F14="","",D14*F14)
F15: =IF(OR(A15="",E15=""),"",INDEX(Guide!$B$83:$D$86,MATCH(A15,Guide!$A$83:$A$86,1),MATCH(E15,Guide!$B$82:$D$82,0))) | G15: =IF(F15="","",D15*F15)
F16: =IF(OR(A16="",E16=""),"",INDEX(Guide!$B$83:$D$86,MATCH(A16,Guide!$A$83:$A$86,1),MATCH(E16,Guide!$B$82:$D$82,0))) | G16: =IF(F16="","",D16*F16)
F17: =IF(OR(A17="",E17=""),"",INDEX(Guide!$B$83:$D$86,MATCH(A17,Guide!$A$83:$A$86,1),MATCH(E17,Guide!$B$82:$D$82,0))) | G17: =IF(F17="","",D17*F17)
F18: =IF(OR(A18="",E18=""),"",INDEX(Guide!$B$83:$D$86,MATCH(A18,Guide!$A$83:$A$86,1),MATCH(E18,Guide!$B$82:$D$82,0))) | G18: =IF(F18="","",D18*F18)
... F156: =IF(OR(A156="",E156=""),"",INDEX(Guide!$B$83:$D$86,MATCH(A156,Guide!$A$83:$A$86,1),MATCH(E156,Guide!$B$82:$D$82,0))) | G156: =IF(F156="","",D156*F156)
C157: Totals | D157: =SUM(D7:D156) | G157: =SUM(G7:G156)
A159: Prepared for planning with Grott Luker & Co. This workbook organizes your records; it does not determine what is deductible. Entries are your own; review with your Grott Luker CPA before anything is used in a return or a decision.

Sheet Expenses
I2: Expenses
I3: ="Tax year "&Log!$B$6&" · Powered by BlueLine Advisors" · Powered by BlueLine Advisors
A5: Business expenses | I5: treatment, counted amount, and watch-outs fill in from the category and your line of work
A6: DATE | B6: CLIENT / VENDOR | C6: WHAT AND WHY | D6: AMOUNT | E6: CATEGORY ▾ | F6: TREATMENT | G6: COUNTED | H6: TYPICAL | I6: WATCH OUT FOR YOUR LINE OF WORK
F7: =IF(E7="","",INDEX(Guide!$B$51:$B$78,MATCH(E7,Guide!$A$51:$A$78,0))) | G7: =IF(OR(E7="",D7=""),"",D7*INDEX(Guide!$C$51:$C$78,MATCH(E7,Guide!$A$51:$A$78,0))) | H7: =IF(E7="","",IF(COUNTIF(INDEX(Guide!$E$25:$R$36,0,Guide!$B$6),E7)>0,"✓","")) | I7: =IF(E7="","",IFERROR(INDEX(INDEX(Guide!$E$44:$R$46,0,Guide!$B$6),MATCH(E7,INDEX(Guide!$E$39:$R$41,0,Guide!$B$6),0)),""))
F8: =IF(E8="","",INDEX(Guide!$B$51:$B$78,MATCH(E8,Guide!$A$51:$A$78,0))) | G8: =IF(OR(E8="",D8=""),"",D8*INDEX(Guide!$C$51:$C$78,MATCH(E8,Guide!$A$51:$A$78,0))) | H8: =IF(E8="","",IF(COUNTIF(INDEX(Guide!$E$25:$R$36,0,Guide!$B$6),E8)>0,"✓","")) | I8: =IF(E8="","",IFERROR(INDEX(INDEX(Guide!$E$44:$R$46,0,Guide!$B$6),MATCH(E8,INDEX(Guide!$E$39:$R$41,0,Guide!$B$6),0)),""))
F9: =IF(E9="","",INDEX(Guide!$B$51:$B$78,MATCH(E9,Guide!$A$51:$A$78,0))) | G9: =IF(OR(E9="",D9=""),"",D9*INDEX(Guide!$C$51:$C$78,MATCH(E9,Guide!$A$51:$A$78,0))) | H9: =IF(E9="","",IF(COUNTIF(INDEX(Guide!$E$25:$R$36,0,Guide!$B$6),E9)>0,"✓","")) | I9: =IF(E9="","",IFERROR(INDEX(INDEX(Guide!$E$44:$R$46,0,Guide!$B$6),MATCH(E9,INDEX(Guide!$E$39:$R$41,0,Guide!$B$6),0)),""))
F10: =IF(E10="","",INDEX(Guide!$B$51:$B$78,MATCH(E10,Guide!$A$51:$A$78,0))) | G10: =IF(OR(E10="",D10=""),"",D10*INDEX(Guide!$C$51:$C$78,MATCH(E10,Guide!$A$51:$A$78,0))) | H10: =IF(E10="","",IF(COUNTIF(INDEX(Guide!$E$25:$R$36,0,Guide!$B$6),E10)>0,"✓","")) | I10: =IF(E10="","",IFERROR(INDEX(INDEX(Guide!$E$44:$R$46,0,Guide!$B$6),MATCH(E10,INDEX(Guide!$E$39:$R$41,0,Guide!$B$6),0)),""))
F11: =IF(E11="","",INDEX(Guide!$B$51:$B$78,MATCH(E11,Guide!$A$51:$A$78,0))) | G11: =IF(OR(E11="",D11=""),"",D11*INDEX(Guide!$C$51:$C$78,MATCH(E11,Guide!$A$51:$A$78,0))) | H11: =IF(E11="","",IF(COUNTIF(INDEX(Guide!$E$25:$R$36,0,Guide!$B$6),E11)>0,"✓","")) | I11: =IF(E11="","",IFERROR(INDEX(INDEX(Guide!$E$44:$R$46,0,Guide!$B$6),MATCH(E11,INDEX(Guide!$E$39:$R$41,0,Guide!$B$6),0)),""))
F12: =IF(E12="","",INDEX(Guide!$B$51:$B$78,MATCH(E12,Guide!$A$51:$A$78,0))) | G12: =IF(OR(E12="",D12=""),"",D12*INDEX(Guide!$C$51:$C$78,MATCH(E12,Guide!$A$51:$A$78,0))) | H12: =IF(E12="","",IF(COUNTIF(INDEX(Guide!$E$25:$R$36,0,Guide!$B$6),E12)>0,"✓","")) | I12: =IF(E12="","",IFERROR(INDEX(INDEX(Guide!$E$44:$R$46,0,Guide!$B$6),MATCH(E12,INDEX(Guide!$E$39:$R$41,0,Guide!$B$6),0)),""))
F13: =IF(E13="","",INDEX(Guide!$B$51:$B$78,MATCH(E13,Guide!$A$51:$A$78,0))) | G13: =IF(OR(E13="",D13=""),"",D13*INDEX(Guide!$C$51:$C$78,MATCH(E13,Guide!$A$51:$A$78,0))) | H13: =IF(E13="","",IF(COUNTIF(INDEX(Guide!$E$25:$R$36,0,Guide!$B$6),E13)>0,"✓","")) | I13: =IF(E13="","",IFERROR(INDEX(INDEX(Guide!$E$44:$R$46,0,Guide!$B$6),MATCH(E13,INDEX(Guide!$E$39:$R$41,0,Guide!$B$6),0)),""))
F14: =IF(E14="","",INDEX(Guide!$B$51:$B$78,MATCH(E14,Guide!$A$51:$A$78,0))) | G14: =IF(OR(E14="",D14=""),"",D14*INDEX(Guide!$C$51:$C$78,MATCH(E14,Guide!$A$51:$A$78,0))) | H14: =IF(E14="","",IF(COUNTIF(INDEX(Guide!$E$25:$R$36,0,Guide!$B$6),E14)>0,"✓","")) | I14: =IF(E14="","",IFERROR(INDEX(INDEX(Guide!$E$44:$R$46,0,Guide!$B$6),MATCH(E14,INDEX(Guide!$E$39:$R$41,0,Guide!$B$6),0)),""))
F15: =IF(E15="","",INDEX(Guide!$B$51:$B$78,MATCH(E15,Guide!$A$51:$A$78,0))) | G15: =IF(OR(E15="",D15=""),"",D15*INDEX(Guide!$C$51:$C$78,MATCH(E15,Guide!$A$51:$A$78,0))) | H15: =IF(E15="","",IF(COUNTIF(INDEX(Guide!$E$25:$R$36,0,Guide!$B$6),E15)>0,"✓","")) | I15: =IF(E15="","",IFERROR(INDEX(INDEX(Guide!$E$44:$R$46,0,Guide!$B$6),MATCH(E15,INDEX(Guide!$E$39:$R$41,0,Guide!$B$6),0)),""))
F16: =IF(E16="","",INDEX(Guide!$B$51:$B$78,MATCH(E16,Guide!$A$51:$A$78,0))) | G16: =IF(OR(E16="",D16=""),"",D16*INDEX(Guide!$C$51:$C$78,MATCH(E16,Guide!$A$51:$A$78,0))) | H16: =IF(E16="","",IF(COUNTIF(INDEX(Guide!$E$25:$R$36,0,Guide!$B$6),E16)>0,"✓","")) | I16: =IF(E16="","",IFERROR(INDEX(INDEX(Guide!$E$44:$R$46,0,Guide!$B$6),MATCH(E16,INDEX(Guide!$E$39:$R$41,0,Guide!$B$6),0)),""))
F17: =IF(E17="","",INDEX(Guide!$B$51:$B$78,MATCH(E17,Guide!$A$51:$A$78,0))) | G17: =IF(OR(E17="",D17=""),"",D17*INDEX(Guide!$C$51:$C$78,MATCH(E17,Guide!$A$51:$A$78,0))) | H17: =IF(E17="","",IF(COUNTIF(INDEX(Guide!$E$25:$R$36,0,Guide!$B$6),E17)>0,"✓","")) | I17: =IF(E17="","",IFERROR(INDEX(INDEX(Guide!$E$44:$R$46,0,Guide!$B$6),MATCH(E17,INDEX(Guide!$E$39:$R$41,0,Guide!$B$6),0)),""))
F18: =IF(E18="","",INDEX(Guide!$B$51:$B$78,MATCH(E18,Guide!$A$51:$A$78,0))) | G18: =IF(OR(E18="",D18=""),"",D18*INDEX(Guide!$C$51:$C$78,MATCH(E18,Guide!$A$51:$A$78,0))) | H18: =IF(E18="","",IF(COUNTIF(INDEX(Guide!$E$25:$R$36,0,Guide!$B$6),E18)>0,"✓","")) | I18: =IF(E18="","",IFERROR(INDEX(INDEX(Guide!$E$44:$R$46,0,Guide!$B$6),MATCH(E18,INDEX(Guide!$E$39:$R$41,0,Guide!$B$6),0)),""))
... F156: =IF(E156="","",INDEX(Guide!$B$51:$B$78,MATCH(E156,Guide!$A$51:$A$78,0))) | G156: =IF(OR(E156="",D156=""),"",D156*INDEX(Guide!$C$51:$C$78,MATCH(E156,Guide!$A$51:$A$78,0))) | H156: =IF(E156="","",IF(COUNTIF(INDEX(Guide!$E$25:$R$36,0,Guide!$B$6),E156)>0,"✓","")) | I156: =IF(E156="","",IFERROR(INDEX(INDEX(Guide!$E$44:$R$46,0,Guide!$B$6),MATCH(E156,INDEX(Guide!$E$39:$R$41,0,Guide!$B$6),0)),""))
C157: Totals | D157: =SUM(D7:D156) | G157: =SUM(G7:G156)
A159: Prepared for planning with Grott Luker & Co. This workbook organizes your records; it does not determine what is deductible. Entries are your own; review with your Grott Luker CPA before anything is used in a return or a decision.

Sheet Summary
F2: Year-end summary
F3: ="Tax year "&Log!$B$6&" · Powered by BlueLine Advisors" · Powered by BlueLine Advisors
A5: ="Prepared for discussion with Grott Luker & Co. · "&Log!$B$9
A7: ESTIMATED DEDUCTIONS — MILEAGE PLUS COUNTED EXPENSES
A8: =Travel!G157+Expenses!G157
A9: =Travel!D157&" miles logged · "&TEXT(Expenses!D157,"$#,##0")&" of expenses logged"
A11: BUSINESS MILES | C11: CHARITY MILES | E11: MEDICAL MILES
A12: =SUMIFS(Travel!$D$7:$D$156,Travel!$E$7:$E$156,"Business") | C12: =SUMIFS(Travel!$D$7:$D$156,Travel!$E$7:$E$156,"Charity") | E12: =SUMIFS(Travel!$D$7:$D$156,Travel!$E$7:$E$156,"Medical")
A13: =TEXT(SUMIFS(Travel!$G$7:$G$156,Travel!$E$7:$E$156,"Business"),"$#,##0.00") | C13: =TEXT(SUMIFS(Travel!$G$7:$G$156,Travel!$E$7:$E$156,"Charity"),"$#,##0.00") | E13: =TEXT(SUMIFS(Travel!$G$7:$G$156,Travel!$E$7:$E$156,"Medical"),"$#,##0.00")
A15: COUNTED IN THE ESTIMATE | C15: FOR CPA REVIEW | E15: NOT DEDUCTIBLE
A16: =SUMIFS(Expenses!$G$7:$G$156,Expenses!$F$7:$F$156,"Deductible")+SUMIFS(Expenses!$G$7:$G$156,Expenses!$F$7:$F$156,"Partly deductible") | C16: =SUMIFS(Expenses!$D$7:$D$156,Expenses!$F$7:$F$156,"For your CPA") | E16: =SUMIFS(Expenses!$D$7:$D$156,Expenses!$F$7:$F$156,"Not deductible")
A17: deductible and partly deductible | C17: equipment, phone, home office, inventory | E17: recorded, counted at zero
A19: Expenses by treatment
A20: TREATMENT | B20: LOGGED | C20: COUNTED | E20: ENTRIES
A21: Deductible | B21: =SUMIFS(Expenses!$D$7:$D$156,Expenses!$F$7:$F$156,"Deductible") | C21: =SUMIFS(Expenses!$G$7:$G$156,Expenses!$F$7:$F$156,"Deductible") | E21: =COUNTIFS(Expenses!$F$7:$F$156,"Deductible",Expenses!$D$7:$D$156,">0")
A22: Partly deductible | B22: =SUMIFS(Expenses!$D$7:$D$156,Expenses!$F$7:$F$156,"Partly deductible") | C22: =SUMIFS(Expenses!$G$7:$G$156,Expenses!$F$7:$F$156,"Partly deductible") | E22: =COUNTIFS(Expenses!$F$7:$F$156,"Partly deductible",Expenses!$D$7:$D$156,">0")
A23: For your CPA | B23: =SUMIFS(Expenses!$D$7:$D$156,Expenses!$F$7:$F$156,"For your CPA") | C23: =SUMIFS(Expenses!$G$7:$G$156,Expenses!$F$7:$F$156,"For your CPA") | E23: =COUNTIFS(Expenses!$F$7:$F$156,"For your CPA",Expenses!$D$7:$D$156,">0")
A24: Not deductible | B24: =SUMIFS(Expenses!$D$7:$D$156,Expenses!$F$7:$F$156,"Not deductible") | C24: =SUMIFS(Expenses!$G$7:$G$156,Expenses!$F$7:$F$156,"Not deductible") | E24: =COUNTIFS(Expenses!$F$7:$F$156,"Not deductible",Expenses!$D$7:$D$156,">0")
A25: All expenses | B25: =SUM(B21:B24) | C25: =SUM(C21:C24) | E25: =SUM(E21:E24)
A27: ="Notes for "&LOWER(LEFT(Log!$B$9,1))&MID(Log!$B$9,2,200)
A28: =T(INDEX(Guide!$E$39:$R$41,1,Guide!$B$6)) | B28: =T(INDEX(Guide!$E$44:$R$46,1,Guide!$B$6))
A29: =T(INDEX(Guide!$E$39:$R$41,2,Guide!$B$6)) | B29: =T(INDEX(Guide!$E$44:$R$46,2,Guide!$B$6))
A30: =T(INDEX(Guide!$E$39:$R$41,3,Guide!$B$6)) | B30: =T(INDEX(Guide!$E$44:$R$46,3,Guide!$B$6))
A32: Reading this
A33: Counted amounts are estimates from the category you chose. Items marked For your CPA are logged but not counted; your CPA places them.
A34: Parking and tolls add to the mileage deduction. Vehicle costs such as gas and repairs are already inside the standard mileage rate.
A36: Prepared for planning with Grott Luker & Co. This workbook organizes your records; it does not determine what is deductible. Entries are your own; review with your Grott Luker CPA before anything is used in a return or a decision.
A38: Grott Luker & Co.
A39: Certified Public Accountants · Portsmouth, New Hampshire · Accounting | Tax Planning | Advisory
A40: Questions about this workbook go to your Grott Luker CPA.
A42: Powered by BlueLine Advisors
A43: The Client Decision Support Toolkit and its templates are built and maintained for Grott Luker & Co. by BlueLine Advisors, LLC, an SEC-registered investment adviser in Exeter, NH (registration does not imply any particular level of skill). Using this workbook does not create an advisory relationship with BlueLine.

Sheet Guide
D2: Guide
D3: Categories, lines of work, and rates · Powered by BlueLine Advisors
A5: Selected line of work (from the Log sheet) | B5: =Log!$B$9
A6: Column of that line of work in the grids below | B6: =IFERROR(MATCH(Log!$B$9,Guide!$E$8:$R$8,0),14)
A8: LINES OF WORK → | E8: Carpenter, contractor, electrician, plumber or other trade | F8: Real estate agent or broker | G8: Doctor, dentist or other health practice | H8: Attorney, consultant, accountant or other professional | I8: Restaurant, caterer or food service | J8: Retail shop or online seller | K8: Rideshare, delivery or trucking | L8: Salon, barber, spa or personal care | M8: Landscaper, cleaner, painter or other home service | N8: IT, software developer or online business | O8: Photographer, designer, writer or other creative | P8: Trainer, coach, instructor or wellness | Q8: Rental property owner | R8: Other / general business
A10: Pay extra attention to these — items | R10: one column per line of work
A11: Item 1 | E11: Blades, bits, sandpaper, fasteners and other consumables | F11: MLS, board and license fees | G11: State license, DEA and board certification fees | H11: Bar, CPA society and licensing fees | I11: Food and beverage purchases | J11: Merchandise purchased for resale | K11: Tolls and paid parking while working | L11: Booth or chair rent | M11: Mowers, blowers, sprayers, machines; note the cost of each | N11: Computers, monitors and peripherals; note the cost of each | O11: Cameras, lenses, lights, computers; note the cost of each | P11: Studio, gym floor or room rent | Q11: Repair and maintenance materials and labor | R11: Meals with clients, business discussed
A12: Item 2 | E12: Hand and power tools; note the cost of each | F12: Lockboxes, yard signs and riders | G12: CME courses and the travel to reach them | H12: CLE, CPE and certification courses | I12: Smallwares, cleaning and paper supplies | J12: Packaging, boxes, labels and postage | K12: Phone plan and mount, business share | L12: Color, product, foils, towels and tools | M12: Fuel for equipment, mulch, chemicals, cleaning supplies | N12: Software, cloud hosting, domains, SaaS tools | O12: Editing software, cloud storage, stock assets | P12: Training equipment; note the cost of each | Q12: Landlord insurance | R12: Overnight travel and lodging
A13: Item 3 | E13: Work boots, gloves, safety glasses, hard hat, hi-vis | F13: Listing photography, staging and marketing | G13: Malpractice insurance | H13: Research, practice and e-signature software | I13: Kitchen equipment; note the cost of each | J13: POS, e-commerce and inventory subscriptions | K13: Passenger water, mints, chargers, cleaning supplies | L13: Chairs, dryers, stations; note the cost of each | M13: Trailer and storage rent | N13: Home office used only for work | O13: Props, backdrops, printing, portfolio materials | P13: Certifications, CEUs and CPR renewal | Q13: Property manager, attorney and accountant fees | R13: Parking and tolls
A14: Item 4 | E14: Dump, disposal and permit fees | F14: Open-house refreshments and flyers | G14: Scrubs, lab coats and clinical footwear | H14: Malpractice or E&O insurance | I14: Staff wages and tips paid out | J14: Marketplace commissions and card fees | K14: Dash cam and phone accessories | L14: License renewals and classes | M14: Helpers and crew you paid | N14: Internet and phone, business share | O14: Portfolio site, ads and directory listings | P14: Liability insurance | Q14: Advertising for tenants and screening fees | R14: Office and job supplies
A15: Item 5 | E15: Subcontractors and helpers you paid | F15: Client closing gifts, $25 per person | G15: Clinical and office supplies | H15: Meals with clients and referral sources | I15: Rent and utilities | J15: Store rent and utilities | K15: Platform and commission fees on your statements | L15: Booking and payment apps | M15: Liability insurance | N15: Courses and certifications | O15: Travel to shoots and client sites | P15: Scheduling, payment and music-licensing subscriptions | Q15: Trips to the property to manage or repair it | R15: Software and subscriptions
A16: Item 6 | E16: Liability and tool insurance | F16: CRM, e-signature and showing apps | G16: Clinical equipment; note the cost of each | H16: Conference travel and lodging | I16: Aprons, chef coats and non-slip shoes | J16: Displays, fixtures and signage | K16: Rideshare insurance rider or commercial policy | L16: Card processing fees | M16: Uniforms, gloves, eye and ear protection | N16: Contractors you paid | O16: Workshops and classes | P16: Card processing fees | Q16: Landlord and bookkeeping software | R16: Phone and internet, business share
A17: Item 7 | E17: Trade license renewals and code classes | F17: Continuing-ed courses and exam fees | G17: EHR, scheduling and billing software | H17: Home office, if used only for work | I17: POS, reservation and delivery-platform fees | J17: Ads, promotions and influencer payments | K17: Background check and vehicle inspection fees | L17: Aprons, smocks and gloves | M17: Dump fees and permits | N17: Payment processor and app-store fees | O17: Gear insurance | P17: Ads, website and social media | Q17: HOA and condo dues | R17: Courses, licenses and certifications
A18: Item 8 | E18: Union dues and trade association fees | F18: Errors & omissions insurance | G18: Staff wages and contract staff | H18: Phone plan, business share | I18: Liquor license, health permits, inspections | J18: Employee wages | K18: Roadside assistance membership | L18: Social ads and business cards | M18: Tolls and parking | N18: Conference travel | O18: Home studio used only for work | P18: Professional association dues | Q18: Utilities you pay for the unit | R18: Professional dues
A19: Item 9 | E19: Trailer, storage unit or shop rent | F19: Parking and tolls at showings and closings | G19: Office rent and utilities | H19: Website, directory listings and sponsorships | I19: Ads, menus, signage and social media | J19: Business insurance | L19: Liability insurance | M19: Yard signs, truck lettering, online ads | N19: Ads and marketing tools | O19: Assistants, models, second shooters | P19: Phone plan, business share | Q19: Improvements: new roof, HVAC, appliances; list each separately | R19: Advertising and website
A20: Item 10 | E20: Job-site parking and tolls | F20: Meals with clients and referral partners | G20: Billing service, attorney, accountant | H20: Bookkeeper, IT support, payroll service | I20: Liability, property and workers’ comp insurance | J20: Trade shows and buying trips | M20: Phone plan, business share | R20: Accountant, attorney and other professional fees
A21: Item 11 | E21: Truck lettering, website, business cards | F21: Phone plan, business share
A22: Item 12 | E22: Phone plan, business share
A24: Pay extra attention to these — category of each item
A25: Item 1 | E25: Supplies & materials | F25: Professional dues & memberships | G25: Professional dues & memberships | H25: Professional dues & memberships | I25: Inventory & cost of goods | J25: Inventory & cost of goods | K25: Parking & tolls | L25: Rent: office, booth, shop, storage, equipment | M25: Equipment, tools & furniture | N25: Equipment, tools & furniture | O25: Equipment, tools & furniture | P25: Rent: office, booth, shop, storage, equipment | Q25: Supplies & materials | R25: Business meal
A26: Item 2 | E26: Equipment, tools & furniture | F26: Supplies & materials | G26: Continuing education, licenses & certifications | H26: Continuing education, licenses & certifications | I26: Supplies & materials | J26: Shipping & postage | K26: Phone & internet | L26: Supplies & materials | M26: Supplies & materials | N26: Software & subscriptions | O26: Software & subscriptions | P26: Equipment, tools & furniture | Q26: Business insurance | R26: Travel: lodging, airfare, rail, rental car
A27: Item 3 | E27: Uniforms & protective gear | F27: Advertising & marketing | G27: Business insurance | H27: Software & subscriptions | I27: Equipment, tools & furniture | J27: Software & subscriptions | K27: Supplies & materials | L27: Equipment, tools & furniture | M27: Rent: office, booth, shop, storage, equipment | N27: Home office | O27: Supplies & materials | P27: Continuing education, licenses & certifications | Q27: Professional, legal & permit fees | R27: Parking & tolls
A28: Item 4 | E28: Professional, legal & permit fees | F28: Advertising & marketing | G28: Uniforms & protective gear | H28: Business insurance | I28: Contract labor & wages | J28: Bank, card & platform fees | K28: Equipment, tools & furniture | L28: Continuing education, licenses & certifications | M28: Contract labor & wages | N28: Phone & internet | O28: Advertising & marketing | P28: Business insurance | Q28: Advertising & marketing | R28: Supplies & materials
A29: Item 5 | E29: Contract labor & wages | F29: Business gifts | G29: Supplies & materials | H29: Business meal | I29: Utilities for business space | J29: Rent: office, booth, shop, storage, equipment | K29: Bank, card & platform fees | L29: Software & subscriptions | M29: Business insurance | N29: Continuing education, licenses & certifications | O29: Travel: lodging, airfare, rail, rental car | P29: Software & subscriptions | Q29: Parking & tolls | R29: Software & subscriptions
A30: Item 6 | E30: Business insurance | F30: Software & subscriptions | G30: Equipment, tools & furniture | H30: Travel: lodging, airfare, rail, rental car | I30: Uniforms & protective gear | J30: Supplies & materials | K30: Business insurance | L30: Bank, card & platform fees | M30: Uniforms & protective gear | N30: Contract labor & wages | O30: Continuing education, licenses & certifications | P30: Bank, card & platform fees | Q30: Software & subscriptions | R30: Phone & internet
A31: Item 7 | E31: Continuing education, licenses & certifications | F31: Continuing education, licenses & certifications | G31: Software & subscriptions | H31: Home office | I31: Bank, card & platform fees | J31: Advertising & marketing | K31: Professional, legal & permit fees | L31: Uniforms & protective gear | M31: Professional, legal & permit fees | N31: Bank, card & platform fees | O31: Business insurance | P31: Advertising & marketing | Q31: Professional dues & memberships | R31: Continuing education, licenses & certifications
A32: Item 8 | E32: Professional dues & memberships | F32: Business insurance | G32: Contract labor & wages | H32: Phone & internet | I32: Professional, legal & permit fees | J32: Contract labor & wages | K32: Professional dues & memberships | L32: Advertising & marketing | M32: Parking & tolls | N32: Travel: lodging, airfare, rail, rental car | O32: Home office | P32: Professional dues & memberships | Q32: Utilities for business space | R32: Professional dues & memberships
A33: Item 9 | E33: Rent: office, booth, shop, storage, equipment | F33: Parking & tolls | G33: Rent: office, booth, shop, storage, equipment | H33: Advertising & marketing | I33: Advertising & marketing | J33: Business insurance | L33: Business insurance | M33: Advertising & marketing | N33: Advertising & marketing | O33: Contract labor & wages | P33: Phone & internet | Q33: Equipment, tools & furniture | R33: Advertising & marketing
A34: Item 10 | E34: Parking & tolls | F34: Business meal | G34: Professional, legal & permit fees | H34: Professional, legal & permit fees | I34: Business insurance | J34: Travel: lodging, airfare, rail, rental car | M34: Phone & internet | R34: Professional, legal & permit fees
A35: Item 11 | E35: Advertising & marketing | F35: Phone & internet
A36: Item 12 | E36: Phone & internet
A38: Usually not deductible — category
A39: Watch-out 1 | E39: Vehicle costs: gas, repairs, car insurance | F39: Commuting | G39: Entertainment | H39: Entertainment | I39: Fines, penalties & tickets | J39: Personal or mixed, unsure | K39: Vehicle costs: gas, repairs, car insurance | L39: Clothing & grooming | M39: Vehicle costs: gas, repairs, car insurance | N39: Home office | O39: Clothing & grooming | P39: Clothing & grooming | Q39: Equipment, tools & furniture | R39: Entertainment
A40: Watch-out 2 | E40: Clothing & grooming | F40: Clothing & grooming | G40: Business meal | H40: Professional dues & memberships | I40: Business meal | J40: Clothing & grooming | K40: Commuting | L40: Personal or mixed, unsure | M40: Fines, penalties & tickets | N40: Phone & internet | O40: Personal or mixed, unsure | P40: Personal or mixed, unsure | Q40: Travel: lodging, airfare, rail, rental car | R40: Clothing & grooming
A41: Watch-out 3 | E41: Fines, penalties & tickets | F41: Entertainment | G41: Clothing & grooming | H41: Clothing & grooming | I41: Personal or mixed, unsure | J41: Commuting | K41: Business meal | L41: Entertainment | M41: Clothing & grooming | N41: Personal or mixed, unsure | O41: Travel: lodging, airfare, rail, rental car | P41: Business meal | Q41: Personal or mixed, unsure | R41: Commuting
A43: Usually not deductible — why
A44: Watch-out 1 | E44: You are on the standard mileage rate here, so truck gas, repairs and insurance are already counted. Do not log them separately. | F44: The first drive of the day from home to the office is commuting. Home straight to a showing usually is not. | G44: Outings for referral sources are entertainment, not marketing. | H44: Client entertainment is not deductible. The meal at the event can be, if billed separately. | I44: Health-code and parking fines are never deductible. | J44: Merchandise you keep for yourself comes out of the deduction. Note it. | K44: Gas, oil, repairs, car washes and car insurance are already inside the standard mileage rate. Log miles, not fuel. | L44: The all-black outfit the salon requires is still everyday clothing. | M44: Truck gas and repairs are inside the standard mileage rate. Fuel for mowers and machines is different: log it under Supplies. | N44: Exclusive use is the test. A desk in the living room does not qualify. | O44: Wardrobe for shoots is not deductible unless it is a costume unusable elsewhere. | P44: Athletic wear is everyday clothing, whatever the logo. | Q44: Improvements are depreciated over years, not deducted now. Describe the work so your CPA can tell a repair from an improvement. | R44: Entertainment is not deductible; the meal portion can be if billed separately.
A45: Watch-out 2 | E45: Jeans, flannels and ordinary boots are everyday wear. Steel-toe boots, hard hats and branded shirts do count. | F45: Business attire is not deductible, however expected in the field. | G45: Staff and vendor lunches are 50%, not 100%. The practice-wide holiday party is the exception. | H45: The club where you meet clients does not count, however useful. Professional societies do. | I45: Meals you provide to staff on premises have their own rules. Keep them separate from client meals. | J45: Wearing what you sell does not make it deductible. | K45: Miles count while the app is on and you are available or en route. Driving home with the app off is personal. | L45: Products you also use at home: only the business share. | M45: Tickets are never deductible. | N45: A shared personal phone is only partly deductible. A second line used only for work is 100%. | O45: Gear you also use on vacation: only the business share. | P45: Your own gym membership and supplements are personal. | Q45: Trips to look at property you do not own are not deductible. | R45: Ordinary clothing is never deductible, however required.
A46: Watch-out 3 | E46: Parking and traffic tickets on the job are never deductible. | F46: Taking a client to a game or a show is entertainment, not marketing. | G46: Ordinary work clothing under the white coat is not deductible. | H46: Suits are not deductible. | I46: Food taken home for the family comes out of cost of goods. Note it. | J46: Driving to your own store each day is commuting. | K46: Lunch between rides is personal. Meals count only on overnight trips away from home. | L46: Client outings are not deductible. | M46: Ordinary work clothes are not deductible; gloves and safety gear are. | N46: Gadgets with real personal use: only the business share. | O46: Trips with a personal component: only the business days and business costs. | P46: Meals with clients are 50% only when business is actually discussed. | Q46: Days you or family use the property reduce the deduction. | R46: Home to your regular workplace is personal.
A49: Expense categories | D49: how each is usually treated
...
